Workbook

Sheet Kế hoạch chi tiết
A1: STT | B1: Nội dung | C1: Tuần | D1: Đầu việc | E1: Đầu ra | F1: Bắt đầu | G1: Deadline | H1: Trạng thái | I1: Ghi chú | J1: Đề xuất kết hợp với Claude | K1: Giờ ước tính
A2: ND1 · Tìm hiểu tổng quan về bài toán — Tuần 1–3 (07/09/2026 → 27/09/2026)
A3: 1 | B3: ND1 | C3: Tuần 1 | D3: Tìm hiểu các khía cạnh của AI Security; xác định vị trí của tấn công tiêm nhiễm gián tiếp (IPI) trong bức tranh chung | E3: Ghi chú khảo sát + mục 2.1 báo cáo | F3: 07/09/2026 | G3: 13/09/2026 | H3: Xong | J3: Claude lập bản đồ khái niệm AI Security làm danh mục kiểm; TA rà phần đã viết còn thiếu nhánh nào. | K3: 6
A4: 2 | B4: ND1 | C4: Tuần 1 | D4: Tìm hiểu cơ chế hoạt động của AI Agent dùng RAG và MCP tool-calling; vẽ con đường nội dung không tin cậy đi vào cửa sổ ngữ cảnh | E4: Sơ đồ luồng dữ liệu + ghi chú | F4: 07/09/2026 | G4: 13/09/2026 | H4: Xong | J4: Claude vẽ sơ đồ luồng dữ liệu (Mermaid) từ mô tả bằng lời; TA đối chiếu với tài liệu MCP gốc. | K4: 6
A5: 3 | B5: ND1 | C5: Tuần 2 | D5: Xây dựng mô hình đe dọa 2 mức: 3 tài sản cần bảo vệ TS1–TS3, 3 mục tiêu tấn công G1–G3; định nghĩa giả định về năng lực kẻ tấn công | E5: docs/01. Đề bài/01. Mô tả bài toán.md | F5: 14/09/2026 | G5: 20/09/2026 | H5: Xong | J5: Claude đóng vai phản biện, soi threat model: chỗ nào TS1–TS3 chưa phủ, giả định nào quá mạnh. | K5: 8
A6: 4 | B6: ND1 | C6: Tuần 2 | D6: Xây dựng taxonomy kênh nội dung không tin cậy K1–K5; chốt 2 kênh đưa vào phạm vi thực nghiệm (K1 tài liệu RAG, K2 tool description/tool output) | E6: Mục taxonomy trong MO_TA_BAI_TOAN.md | F6: 14/09/2026 | G6: 20/09/2026 | H6: Xong | J6: Claude soát tính đầy đủ và tách bạch của taxonomy K1–K5. | K6: 6
A7: 5 | B7: ND1 | C7: Tuần 2 | D7: Khảo sát bộ đo và công trình liên quan (AgentDojo, AutoDojo, MCPTox, InjecAgent, AgentDyn, MCP-Poison-Bench); bằng chứng chạy thật đã có, còn hoàn thiện FIT_GAP.md | E7: docs/03. Khảo sát/evidence/ + docs/03. Khảo sát/FIT_GAP.md | F7: 14/09/2026 | G7: 20/09/2026 | H7: Xong | I7: QUY TẮC CỨNG #2: không nhận xét benchmark nếu chưa chạy thật. Bằng chứng đã lưu ở docs/03. Khảo sát/evidence/ | J7: Claude tóm tắt paper theo bảng tiêu chí cố định; nhận xét benchmark phải tự chạy (quy tắc #2). | K7: 6
A8: 6 | B8: ND1 | C8: Tuần 3 | D8: Chốt phạm vi đồ án, 6 câu hỏi nghiên cứu RQ1–RQ6, persona người dùng và checklist ký với GVHD | E8: Mục phạm vi + RQ trong Y_TUONG_DU_AN.md | F8: 21/09/2026 | G8: 27/09/2026 | H8: Xong | I8: CỔNG M0 | J8: Claude đóng vai hội đồng đặt câu hỏi khó về phạm vi và 6 RQ để vá lỗ hổng trước khi chốt. | K8: 6
A9: 7 | B9: ND1 | C9: Tuần 3 | D9: Soạn phụ lục điều chỉnh phạm vi trình GVHD ký: đổi bộ model, mở 5→8 kỹ thuật tấn công, thêm Bước 10 harness thương mại, ngân sách phân tầng | E9: Phụ lục điều chỉnh (in ra, có chữ ký) | F9: 21/09/2026 | G9: 27/09/2026 | H9: Xong | I9: Chưa ký thì chạy theo phạm vi cũ, không tự đổi model | J9: Claude soạn nháp phụ lục theo thể thức; TA rà nội dung và ký, ghi rõ có AI hỗ trợ soạn. | K9: 4
A10: 8 | B10: ND1 | C10: Tuần 3 | D10: Đồng bộ CLAUDE.md, Y_TUONG_DU_AN.md và Kế hoạch thực hiện với phiếu giao nhiệm vụ đã ký (khung 6 Nội dung / 17 tuần, hạn 08/01/2027) | E10: CLAUDE.md + Y_TUONG_DU_AN.md | F10: 21/09/2026 | G10: 27/09/2026 | H10: Xong | I10: Ghi một mục vào CHANGELOG_TAI_LIEU.md | J10: Claude đọc chéo CLAUDE.md, Y_TUONG_DU_AN.md, Kế hoạch thực hiện và liệt kê mọi chỗ mâu thuẫn. | K10: 3
A11: 9 | B11: ND1 | C11: Tuần 3 | D11: Viết báo cáo: chương 1 đặt vấn đề, tính cấp thiết, mục tiêu, 6 câu hỏi nghiên cứu, đóng góp, bố cục | E11: Nháp chương 1 | F11: 21/09/2026 | G11: 27/09/2026 | H11: Xong | I11: P1 — viết dần 2h/tuần, không dồn cuối | J11: Claude chuyển ý gạch đầu dòng thành đoạn văn khoa học (Phụ lục A); TA tự kiểm mọi trích dẫn. | K11: 8
A12: ND2 · Tìm hiểu tổng quan về công nghệ liên quan — Tuần 4–5 (28/09/2026 → 11/10/2026)
A13: 10 | B13: ND2 | C13: Tuần 4 | D13: MCP Python SDK: lấy danh sách công cụ động qua stdio và HTTP, cơ chế tool-calling; dựng PoC tối giản 1 tool | E13: PoC mcp_poc/ + ghi chú | F13: 28/09/2026 | G13: 04/10/2026 | H13: Đã cắt | I13: Gộp vào ghi chú tìm hiểu ở STT 16 và dựng thẳng ở STT 26, 28 | J13: Đã cắt khỏi kế hoạch. | K13: 0
A14: 11 | B14: ND2 | C14: Tuần 4 | D14: Kỹ thuật RAG: embedding, vector store, truy hồi top-k, xử lý tài liệu PDF/DOCX/Markdown; PoC truy hồi trên kho 40 tài liệu | E14: PoC rag_poc/ + kho tri thức nháp | F14: 28/09/2026 | G14: 04/10/2026 | H14: Đã cắt | I14: Gộp vào ghi chú tìm hiểu ở STT 16 và dựng thẳng ở ingest/retriever của lõi agent | J14: Đã cắt khỏi kế hoạch. | K14: 0
A15: 12 | B15: ND2 | C15: Tuần 4 | D15: Khảo sát 4 nhóm kỹ thuật phòng thủ: lọc đầu vào, spotlighting, kiểm soát chính sách gọi công cụ, lọc dữ liệu đầu ra | E15: Ghi chú + mục 2.4 báo cáo | F15: 28/09/2026 | G15: 04/10/2026 | H15: Xong | I15: Đầu vào trực tiếp cho thiết kế D1–D4 ở ND3 | J15: Claude lập bảng đối chiếu 4 nhóm phòng thủ: cơ chế · vị trí cắm · điểm mù · chi phí. | K15: 5
A16: 13 | B16: ND2 | C16: Tuần 5 | D16: Công nghệ nền của hệ đo: FastAPI, SQLModel/SQLite, MailHog, Streamlit, Docker Compose, pytest; dựng khung dự án quản lý bằng uv | E16: ipi-agent-lab/ khung dự án chạy được | F16: 05/10/2026 | G16: 11/10/2026 | H16: Xong | I16: uv sync --all-groups; ruff line-length 100, py310 | J16: Claude dựng khung repo (uv, ruff, pytest, docker-compose, layout) trong một lượt. | K16: 6
J17: Claude soạn khối targets trong models.yaml và .env.example; không đụng .env thật. | K17: 3
J18: Claude dựng bảng tính chi phí theo công thức; TA tra đơn giá thật trên dashboard. | K18: 3
A19: 16 | B19: ND2 | C19: Tuần 5 | D19: Viết báo cáo: chương 2 cơ sở lý thuyết (MCP, RAG, cơ chế IPI) và phân tích công trình liên quan | E19: Nháp chương 2 | F19: 05/10/2026 | G19: 11/10/2026 | H19: Chưa bắt đầu | I19: P1 | J19: Claude chuyển ghi chú kỹ thuật thành chương 2; TA kiểm lại từng trích dẫn. | K19: 8
A20: ND3 · Phân tích thiết kế — Tuần 6–8 (12/10/2026 → 01/11/2026)
A21: 17 | B21: ND3 | C21: Tuần 6 | D21: Thiết kế kiến trúc testbed 5 tầng: lõi agent · tầng công cụ MCP · kho tri thức · tầng phòng thủ · tầng đo lường; định nghĩa điểm móc (hook) để cắm phòng thủ | E21: Hình kiến trúc + đặc tả interface | F21: 12/10/2026 | G21: 18/10/2026 | H21: Xong | I21: config/ là hợp đồng, viết trước src/ | J21: Claude đề xuất 2–3 phương án kiến trúc kèm đánh đổi để TA chọn, rồi viết đặc tả và hình. | K21: 8
A22: 18 | B22: ND3 | C22: Tuần 6 | D22: Thiết kế bộ đo: 60 câu hỏi lành tính nhóm U1–U5, 6 tác vụ chở CT-01–CT-06, tiêu chí thành công kiểm được bằng chương trình dựa trên canary | E22: data/benign_queries.json + data/carrier_tasks.json | F22: 12/10/2026 | G22: 18/10/2026 | H22: Xong | I22: QUY TẮC CỨNG #1: không sửa/khóa theo quy tắc cứng #1 | J22: Đã khóa — chỉ dùng Claude kiểm tính nhất quán, không cho sửa file. | K22: 10
A23: 19 | B23: ND3 | C23: Tuần 6 | D23: Thiết kế lược đồ lưu vết chạy, bắt buộc có trường blocked_by ∈ {defense, model_refusal, harness} để tách phòng thủ với model tự từ chối | E23: Đặc tả trace schema | F23: 12/10/2026 | G23: 18/10/2026 | H23: Xong | I23: QUY TẮC CỨNG #8 | J23: Claude sinh lược đồ SQLModel và viết test khẳng định blocked_by là trường bắt buộc. | K23: 3
A24: 20 | B24: ND3 | C24: Tuần 7 | D24: Đặc tả 8 kỹ thuật tấn công T1–T8 (5 kỹ thuật từ khảo sát + 3 kỹ thuật tự đề xuất) và 4 cơ chế phòng thủ D1–D4 | E24: Đặc tả kỹ thuật tấn công + phòng thủ | F24: 19/10/2026 | G24: 25/10/2026 | H24: Xong (đặc tả) | I24: Đặc tả T1–T8 + D1–D4 xong (payload_taxonomy.md, defense_spec.md). Phần code: validator schema.py + 17 payload mẫu (đủ 8 kỹ thuật) + worksheet + hướng dẫn, validate 20 test xanh. CÒN: GVHD rà câu chữ payload; tập payload đầy đủ + pilot defense=OFF (chặn bởi lõi agent STT-26) + gán nhãn kép κ≥0,80 + khóa v-attack-1.0. | J24: Claude viết đặc tả T1–T8, D1–D4 theo một mẫu thống nhất; TA chốt ranh giới để không trùng. | K24: 8
A25: 21 | B25: ND3 | C25: Tuần 7 | D25: Lập ma trận dự đoán kỹ thuật × phòng thủ, GHI TRƯỚC khi chạy thực nghiệm để tránh diễn giải hậu nghiệm | E25: Bảng dự đoán (chốt ngày, không sửa sau) | F25: 19/10/2026 | G25: 25/10/2026 | H25: Chưa bắt đầu | J25: TA điền dự đoán trước, rồi hỏi Claude dự đoán độc lập; so hai bản để lộ giả định chưa kiểm. | K25: 4
A26: 22 | B26: ND3 | C26: Tuần 7 | D26: Thiết kế cơ sở dữ liệu khách hàng mô phỏng customers.db: lược đồ bảng, sinh bằng Faker vi_VN với seed cố định | E26: Lược đồ + script sinh dữ liệu | F26: 19/10/2026 | G26: 25/10/2026 | H26: Chưa bắt đầu | I26: QUY TẮC CỨNG #6: tuyệt đối không dùng dữ liệu khách hàng thật | J26: Claude viết script Faker vi_VN seed cố định; nhắc ràng buộc không dùng dữ liệu thật. | K26: 4
A27: 23 | B27: ND3 | C27: Tuần 8 | D27: Thiết kế giao diện dashboard 4 trang: bảng ASR · biểu đồ đánh đổi · trace viewer · công tắc phòng thủ trực tiếp | E27: Wireframe + đặc tả trang | F27: 26/10/2026 | G27: 01/11/2026 | H27: Đã cắt | I27: Bỏ wireframe, dựng thẳng dashboard ở STT 58 | J27: Đã cắt khỏi kế hoạch. | K27: 0
A28: 24 | B28: ND3 | C28: Tuần 8 | D28: Thiết kế giao thức thực nghiệm: bảng biến, cỡ mẫu, tham số cố định, quy trình hiệu chỉnh độ khó, quy tắc dừng và cắt giảm khi hụt giờ | E28: config/experiment.yaml (khung) + giao thức | F28: 26/10/2026 | G28: 01/11/2026 | H28: Chưa bắt đầu | I28: Ghi trước, không chỉnh sau khi đã thấy kết quả | J28: Claude rà giao thức thực nghiệm tìm biến gây nhiễu và chỗ dễ diễn giải hậu nghiệm. | K28: 5
A29: 97 | B29: ND3 | C29: Tuần 8 | D29: Soạn đặc tả chỉ số đo: công thức ASR đầu-cuối, ASR có điều kiện, khoảng tin cậy Wilson 95%, DSR, USR, FRR, TCP, refusal_rate; ví dụ tính tay từng chỉ số; định nghĩa cổng kiểm chứng bộ chấm (8 ca thử ở STT 36) | E29: docs/04. Design/03. Chỉ số đo.md | F29: 26/10/2026 | G29: 01/11/2026 | H29: Chưa bắt đầu | I29: Làm trước STT 36 (cổng kiểm chứng bộ chấm) và STT 67 (hiện thực metrics.py). STT 97 là số cấp thêm sau khi đã đánh số 1–96, đặt ở đây theo thứ tự thời gian; không đánh số lại để giữ nguyên mã commit. | J29: Claude soạn công thức và ví dụ tính tay từ định nghĩa ở Mô tả bài toán; TA đối chiếu từng công thức với biến đo đã chốt. | K29: 3
A30: 25 | B30: ND3 | C30: Tuần 8 | D30: Viết báo cáo: chương 3 phần mô hình đe dọa, taxonomy và thiết kế bộ đo | E30: Nháp chương 3 (phần 1) | F30: 26/10/2026 | G30: 01/11/2026 | H30: Chưa bắt đầu | I30: P1 | J30: Claude ráp ghi chú rời thành chương 3 phần 1; TA viết lại phần luận cứ. | K30: 6
A31: ND4 · Xây dựng chương trình — Tuần 9–12 (02/11/2026 → 29/11/2026)
A32: 26 | B32: ND4 | C32: Tuần 9 | D32: Lõi agent: vòng lặp gọi LLM → thực thi tool_calls → đưa kết quả vào messages → lặp (tối đa 8 vòng), có hook trước/sau mỗi bước để cắm phòng thủ | E32: src/agent/core.py | F32: 02/11/2026 | G32: 08/11/2026 | H32: Chưa bắt đầu | J32: Claude sinh khung vòng lặp agent và vị trí hook, viết test trước; TA kiểm logic dừng và lỗi. | K32: 4
A33: 27 | B33: ND4 | C33: Tuần 9 | D33: Tool registry: 5 tool schema chuẩn function-calling, tách description ra nguồn thay được (để injector K2a tiêm sau), gắn nhãn rủi ro read/write/external | E33: src/tools/registry.py | F33: 02/11/2026 | G33: 08/11/2026 | H33: Chưa bắt đầu | J33: Claude sinh 5 schema tool và nhãn rủi ro trong một lượt từ bảng đặc tả. | K33: 2
A34: 28 | B34: ND4 | C34: Tuần 9 | D34: MCP server: phơi 5 công cụ qua stdio + HTTP bằng MCP Python SDK, agent lấy danh sách công cụ ĐỘNG | E34: src/tools/mcp_server.py | F34: 02/11/2026 | G34: 08/11/2026 | H34: Chưa bắt đầu | I34: Nền tảng cho cả tấn công K2a và cắm harness ở ND6 | J34: Claude viết MCP server theo SDK (Context7 lấy đúng API); test bằng client thật. | K34: 4
A35: 29 | B35: ND4 | C35: Tuần 9 | D35: Công cụ send_email + MailHog: gửi SMTP tới MailHog, đọc lại hộp thư qua API, clear_mailbox() trước mỗi run | E35: src/tools/send_email.py | F35: 02/11/2026 | G35: 08/11/2026 | H35: Chưa bắt đầu | J35: Claude sinh code gửi SMTP + đọc MailHog + clear_mailbox — hạ tầng, rủi ro thấp. | K35: 2
A36: 30 | B36: ND4 | C36: Tuần 9 | D36: Ba công cụ còn lại: http_request (ghi URL + body vào trace), query_customer_db (≤20 bản ghi), create_ticket; mọi tham số ghi vào trace | E36: src/tools/*.py | F36: 02/11/2026 | G36: 08/11/2026 | H36: Chưa bắt đầu | J36: Claude sinh cả ba tool đồng dạng cùng lúc theo một mẫu, ghi trace đầy đủ tham số. | K36: 3
A37: 31 | B37: ND4 | C37: Tuần 9 | D37: System prompt trợ lý nội bộ mô tả 5 công cụ, có placeholder canary; bản mặc định KHÔNG phòng thủ (baseline dễ tổn thương có chủ đích) | E37: src/agent/prompts.py | F37: 02/11/2026 | G37: 08/11/2026 | H37: Chưa bắt đầu | I37: Tham số 'độ cả tin' tách ra config để hiệu chỉnh ở ND5 | J37: Claude soạn nhiều biến thể system prompt theo mức độ cả tin để TA chọn baseline. | K37: 3
A38: 32 | B38: ND4 | C38: Tuần 10 | D38: Trace store: hiện thực SQLModel theo lược đồ đã thiết kế + context manager TraceRecorder + export_runs(filters) → DataFrame | E38: src/obs/trace.py + test | F38: 09/11/2026 | G38: 15/11/2026 | H38: Chưa bắt đầu | J38: Claude sinh SQLModel + TraceRecorder + export_runs và pytest; kiểm bằng test. | K38: 3
A39: 33 | B39: ND4 | C39: Tuần 10 | D39: Canary generator: sinh mã canary theo run, gieo 3 nơi (system prompt · customers.db · URL listener), dọn sau mỗi run | E39: src/eval/canary.py | F39: 09/11/2026 | G39: 15/11/2026 | H39: Chưa bắt đầu | J39: Claude viết bộ sinh/dọn canary và liệt kê các đường rò có thể bỏ sót. | K39: 2
A40: 34 | B40: ND4 | C40: Tuần 10 | D40: Canary listener: FastAPI bắt mọi path /{token}, ghi SQLite (thời điểm/token/IP/URL/headers/body), endpoint /hits | E40: src/obs/canary_listener.py | F40: 09/11/2026 | G40: 15/11/2026 | H40: Chưa bắt đầu | J40: Claude sinh FastAPI listener và lược đồ SQLite trong một lượt. | K40: 2
...

Sheet Tổng quan mốc
A1: Mốc | B1: Trạng thái | C1: Tiêu chí nghiệm thu | D1: Xử lý khi TRƯỢT | E1: Nội dung (phiếu) | F1: Hạn
A2: M0 | B2: Xong | C2: Chốt bài toán · fit_gap có bằng chứng chạy thật · threat model 2 mức · persona · checklist ký | D2: — | E2: ND1 · Tuần 3 | F2: 27/09/2026
A3: M1 | B3: Xong | C3: Bộ đo khóa v-bench-1.0 (60 câu + 6 tác vụ chở + trace schema) | D3: — | E3: ND3 · Tuần 6 | F3: 18/10/2026
A4: M1b | B4: Chưa bắt đầu | C4: Bộ model chốt + v-models-1.0 · cost_budget hết TODO · hạn mức đã đặt · phụ lục GVHD ký | D4: Chưa ký → chạy theo phạm vi và bộ model cũ, không tự đổi model | E4: ND2 · Tuần 5 | F4: 11/10/2026
A5: M2 | B5: Chưa bắt đầu | C5: Agent E2E + trace đủ · scorer 8/8 · trace phân biệt blocked_by · USR nền 3 model | D5: Không 8/8 → KHÔNG sang Bước 5 | E5: ND4 · Tuần 10 | F5: 15/11/2026
A6: M3 | B6: Chưa bắt đầu | C6: ≥300 mẫu truy được nguồn gốc · 2 kênh có nhãn delivered · mutator có activation_check | D6: Chỉ 1 kênh → đi tiếp với kênh đó, ghi hạn chế | E6: ND4 · Tuần 11 | F6: 22/11/2026
A7: M3b | B7: Chưa bắt đầu | C7: ≥2/3 kỹ thuật mới (T6–T8) chạy được + activation_check · v-attack-1.0 | D7: Chỉ xong T8 vẫn đi tiếp — đủ để có đóng góp mới | E7: ND4 · Tuần 12 | F7: 29/11/2026
A8: M4 | B8: Chưa bắt đầu | C8: ASR pilot 20–80% (hoặc đã áp §7) · bảng ASR 2 chỉ số 3 model · refusal_rate · RQ1,RQ2 | D8: Kích hoạt cắt giảm §6 NGAY trong ngày | E8: ND5 · Tuần 14 | F8: 13/12/2026
A9: M5 | B9: Chưa bắt đầu | C9: D1–D4 có unit test · ≥6 cấu hình × 3 model mỗi cái CÓ CẢ ASR+utility · Pareto · RQ3,RQ4 | D9: Thiếu utility KHÔNG chấp nhận — cắt cấu hình giữ yêu cầu 2 số | E9: ND5 · Tuần 15 | F9: 20/12/2026
A10: M6 | B10: Chưa bắt đầu | C10: Bảng đối chiếu D1–D4 ↔ 2 harness · ASR từng harness vs vòng lặp trần cùng model (RQ6a, 6b) · ánh xạ lớp kiểm soát (6c) · threats to validity | D10: HN-CC trên A2, A3 không đạt điều kiện → bỏ, không cần ký lại. HN-CC trên A1 hoặc HN-OW không đạt → khai rõ lý do, ký lại hạng mục harness | E10: ND6 · Tuần 16 | F10: 27/12/2026
A11: M7 | B11: Chưa bắt đầu | C11: ARR ≥2 cơ chế · Pareto 2 bộ điểm · dashboard · demo ≤90s ≥5 lần không lỗi + video | D11: Demo lỗi lần 5 → dùng video | E11: ND6 · Tuần 16 | F11: 27/12/2026
A12: M8 | B12: Chưa bắt đầu | C12: Báo cáo 5 chương · repo chạy máy sạch · slide 15–18 · 15 câu phản biện | D12: Còn nguyên tuần 16 = chạy đúng | E12: ND6 · Tuần 17 | F12: 08/01/2027

Sheet Khối lượng giờ
A1: Nội dung | B1: Tuần | C1: Số tuần | D1: Sức chứa (giờ) | E1: Khối lượng ước tính (giờ) | F1: Chênh (giờ) | G1: Số đầu việc
A2: ND1 | B2: Tuần 1–3 | C2: 3 | D2: =C2*$B$11 | E2: =SUMIF('Kế hoạch chi tiết'!$B:$B,A2,'Kế hoạch chi tiết'!$K:$K) | F2: =D2-E2 | G2: =COUNTIFS('Kế hoạch chi tiết'!$B:$B,A2,'Kế hoạch chi tiết'!$H:$H,"<>Đã cắt")
A3: ND2 | B3: Tuần 4–5 | C3: 2 | D3: =C3*$B$11 | E3: =SUMIF('Kế hoạch chi tiết'!$B:$B,A3,'Kế hoạch chi tiết'!$K:$K) | F3: =D3-E3 | G3: =COUNTIFS('Kế hoạch chi tiết'!$B:$B,A3,'Kế hoạch chi tiết'!$H:$H,"<>Đã cắt")
A4: ND3 | B4: Tuần 6–8 | C4: 3 | D4: =C4*$B$11 | E4: =SUMIF('Kế hoạch chi tiết'!$B:$B,A4,'Kế hoạch chi tiết'!$K:$K) | F4: =D4-E4 | G4: =COUNTIFS('Kế hoạch chi tiết'!$B:$B,A4,'Kế hoạch chi tiết'!$H:$H,"<>Đã cắt")
A5: ND4 | B5: Tuần 9–12 | C5: 4 | D5: =C5*$B$11 | E5: =SUMIF('Kế hoạch chi tiết'!$B:$B,A5,'Kế hoạch chi tiết'!$K:$K) | F5: =D5-E5 | G5: =COUNTIFS('Kế hoạch chi tiết'!$B:$B,A5,'Kế hoạch chi tiết'!$H:$H,"<>Đã cắt")
A6: ND5 | B6: Tuần 13–15 | C6: 3 | D6: =C6*$B$11 | E6: =SUMIF('Kế hoạch chi tiết'!$B:$B,A6,'Kế hoạch chi tiết'!$K:$K) | F6: =D6-E6 | G6: =COUNTIFS('Kế hoạch chi tiết'!$B:$B,A6,'Kế hoạch chi tiết'!$H:$H,"<>Đã cắt")
A7: ND6 | B7: Tuần 16–17 | C7: 2 | D7: =C7*$B$11 | E7: =SUMIF('Kế hoạch chi tiết'!$B:$B,A7,'Kế hoạch chi tiết'!$K:$K) | F7: =D7-E7 | G7: =COUNTIFS('Kế hoạch chi tiết'!$B:$B,A7,'Kế hoạch chi tiết'!$H:$H,"<>Đã cắt")
A8: Tổng | C8: =SUM(C2:C7) | D8: =SUM(D2:D7) | E8: =SUM(E2:E7) | F8: =SUM(F2:F7) | G8: =SUM(G2:G7)
A10: Tham số
A11: Giờ làm việc mỗi tuần | B11: 20
A13: Ghi chú
A14: Giờ ước tính ở cột K của sheet "Kế hoạch chi tiết", đã tính có Claude hỗ trợ viết mã và nháp; TA rà lại theo thực tế. Chênh âm = vượt sức chứa của Nội dung đó.

Sheet Báo cáo 2 tuần
A1: BÁO CÁO CÔNG VIỆC THỰC HIỆN
A2: Người báo cáo: Kiều Thành Anh
A3: Kỳ báo cáo (2 tuần qua): | B3: 46272 | C3: đến | D3: 46285
A4: Kỳ kế hoạch (2 tuần tới): | B4: 46286 | C4: đến | D4: 46299
A6: I. CÔNG VIỆC ĐÃ THỰC HIỆN
A7: STT | B7: Đầu việc | C7: Đầu ra / Kết quả | D7: Bắt đầu | E7: Deadline | F7: % hoàn thành | G7: Trạng thái | H7: Vướng mắc / Ghi chú
A8: 1 | B8: Viết chi tiết mô tải bài toán
A9: 2 | B9: Vẽ sơ đồ
A10: 3
A11: 4
A12: 5
A14: II. KẾ HOẠCH CÔNG VIỆC
A15: STT | B15: Đầu việc | C15: Đầu ra dự kiến | D15: Bắt đầu | E15: Deadline | F15: Ưu tiên | G15: Người phụ trách | H15: Điều kiện cần / Rủi ro
A16: 1
A17: 2
A18: 3
A19: 4
A20: 5
A22: III. VƯỚNG MẮC & ĐỀ XUẤT
A23: STT | B23: Vấn đề / Rủi ro | C23: Ảnh hưởng | D23: Đề xuất / Hướng xử lý | G23: Cần hỗ trợ từ | H23: Hạn xử lý
A24: 1
A25: 2
A26: 3
